<?xml version="1.0" ?>
<robot name="than_xe_backup" xmlns:xacro="http://www.ros.org/wiki/xacro">

<xacro:include filename="$(find than_xe_backup_description)/urdf/materials.xacro" />
<xacro:include filename="$(find than_xe_backup_description)/urdf/than_xe_backup.trans" />
<xacro:include filename="$(find than_xe_backup_description)/urdf/than_xe_backup.gazebo" />
<link name="base_link">
  <inertial>
    <origin xyz="0.0370064191341632 -0.0012085384767595287 0.6336765540680926" rpy="0 0 0"/>
    <mass value="4808.877187166819"/>
    <inertia ixx="802.406036" iyy="1467.787259" izz="994.196717" ixy="4.876369" iyz="-2.186078" ixz="-5.572851"/>
  </inertial>
  <visual>
    <origin xyz="0 0 0" rpy="0 0 0"/>
    <geometry>
      <mesh filename="file://$(find than_xe_backup_description)/meshes/base_link.stl" scale="0.001 0.001 0.001"/>
    </geometry>
    <material name="silver"/>
  </visual>
  <collision>
    <origin xyz="0 0 0" rpy="0 0 0"/>
    <geometry>
      <mesh filename="file://$(find than_xe_backup_description)/meshes/base_link.stl" scale="0.001 0.001 0.001"/>
    </geometry>
  </collision>
</link>

<link name="wheel1_1">
  <inertial>
    <origin xyz="6.062106372439757e-11 0.00043646564249066877 -3.530163661391583e-11" rpy="0 0 0"/>
    <mass value="7.035084944105409"/>
    <inertia ixx="0.045298" iyy="0.079257" izz="0.045298" ixy="0.0" iyz="0.0" ixz="0.0"/>
  </inertial>
  <visual>
    <origin xyz="-0.65 -0.35225 -0.1015" rpy="0 0 0"/>
    <geometry>
      <mesh filename="file://$(find than_xe_backup_description)/meshes/wheel1_1.stl" scale="0.001 0.001 0.001"/>
    </geometry>
    <material name="silver"/>
  </visual>
  <collision>
    <origin xyz="-0.65 -0.35225 -0.1015" rpy="0 0 0"/>
    <geometry>
      <mesh filename="file://$(find than_xe_backup_description)/meshes/wheel1_1.stl" scale="0.001 0.001 0.001"/>
    </geometry>
  </collision>
</link>

<link name="wheel2_1">
  <inertial>
    <origin xyz="6.069045266343664e-11 -0.0004364656424908908 3.517806879127505e-11" rpy="0 0 0"/>
    <mass value="7.035084944105409"/>
    <inertia ixx="0.045298" iyy="0.079257" izz="0.045298" ixy="-0.0" iyz="0.0" ixz="-0.0"/>
  </inertial>
  <visual>
    <origin xyz="-0.64925 0.35225 -0.0982" rpy="0 0 0"/>
    <geometry>
      <mesh filename="file://$(find than_xe_backup_description)/meshes/wheel2_1.stl" scale="0.001 0.001 0.001"/>
    </geometry>
    <material name="silver"/>
  </visual>
  <collision>
    <origin xyz="-0.64925 0.35225 -0.0982" rpy="0 0 0"/>
    <geometry>
      <mesh filename="file://$(find than_xe_backup_description)/meshes/wheel2_1.stl" scale="0.001 0.001 0.001"/>
    </geometry>
  </collision>
</link>

<link name="wheel4_1">
  <inertial>
    <origin xyz="-4.4986378688882667e-07 0.0004364656424904467 2.8897391064763855e-07" rpy="0 0 0"/>
    <mass value="7.035084944105409"/>
    <inertia ixx="0.045298" iyy="0.079257" izz="0.045298" ixy="-0.0" iyz="-0.0" ixz="0.0"/>
  </inertial>
  <visual>
    <origin xyz="0.653595 -0.35225 -0.098109" rpy="0 0 0"/>
    <geometry>
      <mesh filename="file://$(find than_xe_backup_description)/meshes/wheel4_1.stl" scale="0.001 0.001 0.001"/>
    </geometry>
    <material name="silver"/>
  </visual>
  <collision>
    <origin xyz="0.653595 -0.35225 -0.098109" rpy="0 0 0"/>
    <geometry>
      <mesh filename="file://$(find than_xe_backup_description)/meshes/wheel4_1.stl" scale="0.001 0.001 0.001"/>
    </geometry>
  </collision>
</link>

<link name="wheel3_1">
  <inertial>
    <origin xyz="4.4810785126969677e-07 -0.00043646564249105735 6.14744366522757e-13" rpy="0 0 0"/>
    <mass value="7.035084944105409"/>
    <inertia ixx="0.045298" iyy="0.079257" izz="0.045298" ixy="0.0" iyz="-0.0" ixz="-0.0"/>
  </inertial>
  <visual>
    <origin xyz="0.652962 0.341 -0.102" rpy="0 0 0"/>
    <geometry>
      <mesh filename="file://$(find than_xe_backup_description)/meshes/wheel3_1.stl" scale="0.001 0.001 0.001"/>
    </geometry>
    <material name="silver"/>
  </visual>
  <collision>
    <origin xyz="0.652962 0.341 -0.102" rpy="0 0 0"/>
    <geometry>
      <mesh filename="file://$(find than_xe_backup_description)/meshes/wheel3_1.stl" scale="0.001 0.001 0.001"/>
    </geometry>
  </collision>
</link>

<link name="motor1_1">
  <inertial>
    <origin xyz="-0.65 -0.295 -0.03" rpy="0 0 0"/>
    <mass value="0.0"/>
    <inertia ixx="0.0" iyy="0.0" izz="0.0" ixy="0.0" iyz="0.0" ixz="0.0"/>
  </inertial>
  <visual>
    <origin xyz="-0.65 -0.295 -0.03" rpy="0 0 0"/>
    <geometry>
      <mesh filename="file://$(find than_xe_backup_description)/meshes/motor1_1.stl" scale="0.001 0.001 0.001"/>
    </geometry>
    <material name="silver"/>
  </visual>
  <collision>
    <origin xyz="-0.65 -0.295 -0.03" rpy="0 0 0"/>
    <geometry>
      <mesh filename="file://$(find than_xe_backup_description)/meshes/motor1_1.stl" scale="0.001 0.001 0.001"/>
    </geometry>
  </collision>
</link>

<link name="motor2_1">
  <inertial>
    <origin xyz="-0.65 0.295 -0.03" rpy="0 0 0"/>
    <mass value="0.0"/>
    <inertia ixx="0.0" iyy="0.0" izz="0.0" ixy="0.0" iyz="0.0" ixz="0.0"/>
  </inertial>
  <visual>
    <origin xyz="-0.65 0.295 -0.03" rpy="0 0 0"/>
    <geometry>
      <mesh filename="file://$(find than_xe_backup_description)/meshes/motor2_1.stl" scale="0.001 0.001 0.001"/>
    </geometry>
    <material name="silver"/>
  </visual>
  <collision>
    <origin xyz="-0.65 0.295 -0.03" rpy="0 0 0"/>
    <geometry>
      <mesh filename="file://$(find than_xe_backup_description)/meshes/motor2_1.stl" scale="0.001 0.001 0.001"/>
    </geometry>
  </collision>
</link>

<link name="motor3_1">
  <inertial>
    <origin xyz="0.65 -0.295 -0.03" rpy="0 0 0"/>
    <mass value="0.0"/>
    <inertia ixx="0.0" iyy="0.0" izz="0.0" ixy="0.0" iyz="0.0" ixz="0.0"/>
  </inertial>
  <visual>
    <origin xyz="0.65 -0.295 -0.03" rpy="0 0 0"/>
    <geometry>
      <mesh filename="file://$(find than_xe_backup_description)/meshes/motor3_1.stl" scale="0.001 0.001 0.001"/>
    </geometry>
    <material name="silver"/>
  </visual>
  <collision>
    <origin xyz="0.65 -0.295 -0.03" rpy="0 0 0"/>
    <geometry>
      <mesh filename="file://$(find than_xe_backup_description)/meshes/motor3_1.stl" scale="0.001 0.001 0.001"/>
    </geometry>
  </collision>
</link>

<joint name="wheel1_to_motor1" type="continuous">
  <origin xyz="0.0 0.05725 0.0715" rpy="0 0 0"/>
  <parent link="motor1_1"/>
  <child link="wheel1_1"/>
  <axis xyz="0.0 1.0 -0.0"/>
</joint>

<joint name="wheel2_to_motor2" type="continuous">
  <origin xyz="-0.00075 -0.05725 0.0682" rpy="0 0 0"/>
  <parent link="motor2_1"/>
  <child link="wheel2_1"/>
  <axis xyz="0.0 -1.0 0.0"/>
</joint>

<joint name="wheel3_to_motor3" type="continuous">
  <origin xyz="-0.003595 0.05725 0.068109" rpy="0 0 0"/>
  <parent link="motor3_1"/>
  <child link="wheel4_1"/>
  <axis xyz="0.0 1.0 0.0"/>
</joint>

<joint name="wheel4_to_base_link" type="continuous">
  <origin xyz="-0.652962 -0.341 0.102" rpy="0 0 0"/>
  <parent link="base_link"/>
  <child link="wheel3_1"/>
  <axis xyz="-0.0 -1.0 0.0"/>
</joint>

<joint name="motor1_to_base_link" type="fixed">
  <origin xyz="0.65 0.295 0.03" rpy="0 0 0"/>
  <parent link="base_link"/>
  <child link="motor1_1"/>
</joint>

<joint name="motor2_to_base_link" type="fixed">
  <origin xyz="0.65 -0.295 0.03" rpy="0 0 0"/>
  <parent link="base_link"/>
  <child link="motor2_1"/>
</joint>

<joint name="motor3_to_base_link" type="fixed">
  <origin xyz="-0.65 0.295 0.03" rpy="0 0 0"/>
  <parent link="base_link"/>
  <child link="motor3_1"/>
</joint>

</robot>
